Workbook

Sheet 使い方
A1: 🐪 | B1: 夫婦で実践｜サイドFIRE計画シート v4.1
B2: 貯金と運用を分離・生活費は内訳から自動・読みやすい〇万円表示付き
B4: ■ 読む順番
B5: ①使い方 (このページ)
B6: ②生活費 ← 月の支出を項目別に入力
B7: ③入力 ← 黄色セル全部書き換える（年齢・収入・資産・投資設定）
B8: ④🎯 結論 ← ここを開けば全部わかる
B9: ⑤年次推移 ← 何歳でいくら持てるか
B10: ⑥FIRE試算 ← 別シナリオ比較
B12: ■ 「〇万円」表示について
B13: ・大きい桁の数字（億・千万）は右隣のセルに『〇億〇万円』形式で表示されます
B14: ・例: 30,000,000円 → 「3,000万円」
B15: ・例: 150,000,000円 → 「1億5,000万円」
... B25: → 4%ルールは米国実績、日本では3-3.5%推奨説あり

Sheet 生活費
A1: 🐪 | B1: 生活費｜月の家計内訳
B2: 🟡黄色セルに金額入力 → 合計が『入力』シートに自動反映 / 右に万円表示
A4: 📌 今の月の生活費（現在）
B5: 項目 | C5: 月額 | D5: 万円表示 | F5: 備考
B6: 住居費 | C6: 90000 | D6: =IF(NOT(ISNUMBER(C6)),"",IF(ABS(C6)>=100000000,TEXT(INT(C6/100000000),"0")&"億"&IF(MOD(C6,100000000)>=10000,TEXT(ROUND(MOD(C6,100000000)/10000,0),"#,##0")&"万円","円"),IF(ABS(C6)>=10000,TEXT(ROUND(C6/10000,0),"#,##0")&"万円",TEXT(C6,"#,##0")&"円"))) | F6: 家賃・住宅ローン・管理費
B7: 食費 | C7: 80000 | D7: =IF(NOT(ISNUMBER(C7)),"",IF(ABS(C7)>=100000000,TEXT(INT(C7/100000000),"0")&"億"&IF(MOD(C7,100000000)>=10000,TEXT(ROUND(MOD(C7,100000000)/10000,0),"#,##0")&"万円","円"),IF(ABS(C7)>=10000,TEXT(ROUND(C7/10000,0),"#,##0")&"万円",TEXT(C7,"#,##0")&"円"))) | F7: 自炊中心＋外食少し
B8: 水道光熱費 | C8: 22000 | D8: =IF(NOT(ISNUMBER(C8)),"",IF(ABS(C8)>=100000000,TEXT(INT(C8/100000000),"0")&"億"&IF(MOD(C8,100000000)>=10000,TEXT(ROUND(MOD(C8,100000000)/10000,0),"#,##0")&"万円","円"),IF(ABS(C8)>=10000,TEXT(ROUND(C8/10000,0),"#,##0")&"万円",TEXT(C8,"#,##0")&"円"))) | F8: 電気・ガス・水道
B9: 通信費 | C9: 18000 | D9: =IF(NOT(ISNUMBER(C9)),"",IF(ABS(C9)>=100000000,TEXT(INT(C9/100000000),"0")&"億"&IF(MOD(C9,100000000)>=10000,TEXT(ROUND(MOD(C9,100000000)/10000,0),"#,##0")&"万円","円"),IF(ABS(C9)>=10000,TEXT(ROUND(C9/10000,0),"#,##0")&"万円",TEXT(C9,"#,##0")&"円"))) | F9: スマホ＋ネット
B10: 日用品 | C10: 12000 | D10: =IF(NOT(ISNUMBER(C10)),"",IF(ABS(C10)>=100000000,TEXT(INT(C10/100000000),"0")&"億"&IF(MOD(C10,100000000)>=10000,TEXT(ROUND(MOD(C10,100000000)/10000,0),"#,##0")&"万円","円"),IF(ABS(C10)>=10000,TEXT(ROUND(C10/10000,0),"#,##0")&"万円",TEXT(C10,"#,##0")&"円"))) | F10: 消耗品・雑貨
B11: 交通費 | C11: 20000 | D11: =IF(NOT(ISNUMBER(C11)),"",IF(ABS(C11)>=100000000,TEXT(INT(C11/100000000),"0")&"億"&IF(MOD(C11,100000000)>=10000,TEXT(ROUND(MOD(C11,100000000)/10000,0),"#,##0")&"万円","円"),IF(ABS(C11)>=10000,TEXT(ROUND(C11/10000,0),"#,##0")&"万円",TEXT(C11,"#,##0")&"円"))) | F11: 車・公共交通
B12: 医療・保険 | C12: 15000 | D12: =IF(NOT(ISNUMBER(C12)),"",IF(ABS(C12)>=100000000,TEXT(INT(C12/100000000),"0")&"億"&IF(MOD(C12,100000000)>=10000,TEXT(ROUND(MOD(C12,100000000)/10000,0),"#,##0")&"万円","円"),IF(ABS(C12)>=10000,TEXT(ROUND(C12/10000,0),"#,##0")&"万円",TEXT(C12,"#,##0")&"円"))) | F12: 医療費＋保険料
B13: 娯楽・交際費 | C13: 25000 | D13: =IF(NOT(ISNUMBER(C13)),"",IF(ABS(C13)>=100000000,TEXT(INT(C13/100000000),"0")&"億"&IF(MOD(C13,100000000)>=10000,TEXT(ROUND(MOD(C13,100000000)/10000,0),"#,##0")&"万円","円"),IF(ABS(C13)>=10000,TEXT(ROUND(C13/10000,0),"#,##0")&"万円",TEXT(C13,"#,##0")&"円"))) | F13: レジャー・外食
B14: 社会保険料 | C14: 40000 | D14: =IF(NOT(ISNUMBER(C14)),"",IF(ABS(C14)>=100000000,TEXT(INT(C14/100000000),"0")&"億"&IF(MOD(C14,100000000)>=10000,TEXT(ROUND(MOD(C14,100000000)/10000,0),"#,##0")&"万円","円"),IF(ABS(C14)>=10000,TEXT(ROUND(C14/10000,0),"#,##0")&"万円",TEXT(C14,"#,##0")&"円"))) | F14: 国保・年金等
B15: 教育費 | C15: 0 | D15: =IF(NOT(ISNUMBER(C15)),"",IF(ABS(C15)>=100000000,TEXT(INT(C15/100000000),"0")&"億"&IF(MOD(C15,100000000)>=10000,TEXT(ROUND(MOD(C15,100000000)/10000,0),"#,##0")&"万円","円"),IF(ABS(C15)>=10000,TEXT(ROUND(C15/10000,0),"#,##0")&"万円",TEXT(C15,"#,##0")&"円"))) | F15: 子どもがいる場合のみ
B16: その他 | C16: 0 | D16: =IF(NOT(ISNUMBER(C16)),"",IF(ABS(C16)>=100000000,TEXT(INT(C16/100000000),"0")&"億"&IF(MOD(C16,100000000)>=10000,TEXT(ROUND(MOD(C16,100000000)/10000,0),"#,##0")&"万円","円"),IF(ABS(C16)>=10000,TEXT(ROUND(C16/10000,0),"#,##0")&"万円",TEXT(C16,"#,##0")&"円"))) | F16: 雑費
B17: 🔢 合計（月） | C17: =SUM(C6:C16) | D17: =IF(NOT(ISNUMBER(C17)),"",IF(ABS(C17)>=100000000,TEXT(INT(C17/100000000),"0")&"億"&IF(MOD(C17,100000000)>=10000,TEXT(ROUND(MOD(C17,100000000)/10000,0),"#,##0")&"万円","円"),IF(ABS(C17)>=10000,TEXT(ROUND(C17/10000,0),"#,##0")&"万円",TEXT(C17,"#,##0")&"円"))) | F17: ← 『入力』シートに自動反映
A19: 📌 FIRE後の想定生活費（仕事減らした後）
B20: 項目 | C20: 月額 | D20: 万円表示 | F20: 変化
B21: 住居費 | C21: 90000 | D21: =IF(NOT(ISNUMBER(C21)),"",IF(ABS(C21)>=100000000,TEXT(INT(C21/100000000),"0")&"億"&IF(MOD(C21,100000000)>=10000,TEXT(ROUND(MOD(C21,100000000)/10000,0),"#,##0")&"万円","円"),IF(ABS(C21)>=10000,TEXT(ROUND(C21/10000,0),"#,##0")&"万円",TEXT(C21,"#,##0")&"円"))) | F21: ローン完済なら下がる
B22: 食費 | C22: 70000 | D22: =IF(NOT(ISNUMBER(C22)),"",IF(ABS(C22)>=100000000,TEXT(INT(C22/100000000),"0")&"億"&IF(MOD(C22,100000000)>=10000,TEXT(ROUND(MOD(C22,100000000)/10000,0),"#,##0")&"万円","円"),IF(ABS(C22)>=10000,TEXT(ROUND(C22/10000,0),"#,##0")&"万円",TEXT(C22,"#,##0")&"円"))) | F22: 在宅で少し下がる
B23: 水道光熱費 | C23: 25000 | D23: =IF(NOT(ISNUMBER(C23)),"",IF(ABS(C23)>=100000000,TEXT(INT(C23/100000000),"0")&"億"&IF(MOD(C23,100000000)>=10000,TEXT(ROUND(MOD(C23,100000000)/10000,0),"#,##0")&"万円","円"),IF(ABS(C23)>=10000,TEXT(ROUND(C23/10000,0),"#,##0")&"万円",TEXT(C23,"#,##0")&"円"))) | F23: 在宅で少し上がる
B24: 通信費 | C24: 18000 | D24: =IF(NOT(ISNUMBER(C24)),"",IF(ABS(C24)>=100000000,TEXT(INT(C24/100000000),"0")&"億"&IF(MOD(C24,100000000)>=10000,TEXT(ROUND(MOD(C24,100000000)/10000,0),"#,##0")&"万円","円"),IF(ABS(C24)>=10000,TEXT(ROUND(C24/10000,0),"#,##0")&"万円",TEXT(C24,"#,##0")&"円"))) | F24: 変わらず
B25: 日用品 | C25: 12000 | D25: =IF(NOT(ISNUMBER(C25)),"",IF(ABS(C25)>=100000000,TEXT(INT(C25/100000000),"0")&"億"&IF(MOD(C25,100000000)>=10000,TEXT(ROUND(MOD(C25,100000000)/10000,0),"#,##0")&"万円","円"),IF(ABS(C25)>=10000,TEXT(ROUND(C25/10000,0),"#,##0")&"万円",TEXT(C25,"#,##0")&"円"))) | F25: 変わらず
B26: 交通費 | C26: 15000 | D26: =IF(NOT(ISNUMBER(C26)),"",IF(ABS(C26)>=100000000,TEXT(INT(C26/100000000),"0")&"億"&IF(MOD(C26,100000000)>=10000,TEXT(ROUND(MOD(C26,100000000)/10000,0),"#,##0")&"万円","円"),IF(ABS(C26)>=10000,TEXT(ROUND(C26/10000,0),"#,##0")&"万円",TEXT(C26,"#,##0")&"円"))) | F26: 通勤費減
B27: 医療・保険 | C27: 30000 | D27: =IF(NOT(ISNUMBER(C27)),"",IF(ABS(C27)>=100000000,TEXT(INT(C27/100000000),"0")&"億"&IF(MOD(C27,100000000)>=10000,TEXT(ROUND(MOD(C27,100000000)/10000,0),"#,##0")&"万円","円"),IF(ABS(C27)>=10000,TEXT(ROUND(C27/10000,0),"#,##0")&"万円",TEXT(C27,"#,##0")&"円"))) | F27: 国保＋年齢上昇
B28: 娯楽・交際費 | C28: 35000 | D28: =IF(NOT(ISNUMBER(C28)),"",IF(ABS(C28)>=100000000,TEXT(INT(C28/100000000),"0")&"億"&IF(MOD(C28,100000000)>=10000,TEXT(ROUND(MOD(C28,100000000)/10000,0),"#,##0")&"万円","円"),IF(ABS(C28)>=10000,TEXT(ROUND(C28/10000,0),"#,##0")&"万円",TEXT(C28,"#,##0")&"円"))) | F28: 時間できて増える
B29: 社会保険料 | C29: 0 | D29: =IF(NOT(ISNUMBER(C29)),"",IF(ABS(C29)>=100000000,TEXT(INT(C29/100000000),"0")&"億"&IF(MOD(C29,100000000)>=10000,TEXT(ROUND(MOD(C29,100000000)/10000,0),"#,##0")&"万円","円"),IF(ABS(C29)>=10000,TEXT(ROUND(C29/10000,0),"#,##0")&"万円",TEXT(C29,"#,##0")&"円"))) | F29: 副業のみなら大幅減
B30: 教育費 | C30: 30000 | D30: =IF(NOT(ISNUMBER(C30)),"",IF(ABS(C30)>=100000000,TEXT(INT(C30/100000000),"0")&"億"&IF(MOD(C30,100000000)>=10000,TEXT(ROUND(MOD(C30,100000000)/10000,0),"#,##0")&"万円","円"),IF(ABS(C30)>=10000,TEXT(ROUND(C30/10000,0),"#,##0")&"万円",TEXT(C30,"#,##0")&"円"))) | F30: 子供想定（任意）
B31: その他 | C31: 5000 | D31: =IF(NOT(ISNUMBER(C31)),"",IF(ABS(C31)>=100000000,TEXT(INT(C31/100000000),"0")&"億"&IF(MOD(C31,100000000)>=10000,TEXT(ROUND(MOD(C31,100000000)/10000,0),"#,##0")&"万円","円"),IF(ABS(C31)>=10000,TEXT(ROUND(C31/10000,0),"#,##0")&"万円",TEXT(C31,"#,##0")&"円"))) | F31: 趣味等
B32: 🔢 FIRE後合計（月） | C32: =SUM(C21:C31) | D32: =IF(NOT(ISNUMBER(C32)),"",IF(ABS(C32)>=100000000,TEXT(INT(C32/100000000),"0")&"億"&IF(MOD(C32,100000000)>=10000,TEXT(ROUND(MOD(C32,100000000)/10000,0),"#,##0")&"万円","円"),IF(ABS(C32)>=10000,TEXT(ROUND(C32/10000,0),"#,##0")&"万円",TEXT(C32,"#,##0")&"円"))) | F32: ← 『入力』シートに自動反映

Sheet 入力
A1: 🐪 | B1: 入力｜🟡黄色セルだけ書き換える
B2: 全11項目・5分で埋まる / 値の右に万円表示
A4: 👤 基本情報
B5: 現在年齢 | C5: 27 | E5: (夫婦のうち年上の方)
B6: 目標 FIRE 年齢 | C6: 45 | E6: (何歳でセミリタイア？)
A8: 💰 夫婦の月収入
B9: 夫婦の月手取り合計 | C9: 450000 | D9: =IF(NOT(ISNUMBER(C9)),"",IF(ABS(C9)>=100000000,TEXT(INT(C9/100000000),"0")&"億"&IF(MOD(C9,100000000)>=10000,TEXT(ROUND(MOD(C9,100000000)/10000,0),"#,##0")&"万円","円"),IF(ABS(C9)>=10000,TEXT(ROUND(C9/10000,0),"#,##0")&"万円",TEXT(C9,"#,##0")&"円"))) | E9: (2人の手取り合計)
B10: 夫婦のボーナス年合計 | C10: 1600000 | D10: =IF(NOT(ISNUMBER(C10)),"",IF(ABS(C10)>=100000000,TEXT(INT(C10/100000000),"0")&"億"&IF(MOD(C10,100000000)>=10000,TEXT(ROUND(MOD(C10,100000000)/10000,0),"#,##0")&"万円","円"),IF(ABS(C10)>=10000,TEXT(ROUND(C10/10000,0),"#,##0")&"万円",TEXT(C10,"#,##0")&"円"))) | E10: (2人の年ボーナス手取り合計)
B11: 🔢 年手取り合計 | C11: =C9*12+C10 | D11: =IF(NOT(ISNUMBER(C11)),"",IF(ABS(C11)>=100000000,TEXT(INT(C11/100000000),"0")&"億"&IF(MOD(C11,100000000)>=10000,TEXT(ROUND(MOD(C11,100000000)/10000,0),"#,##0")&"万円","円"),IF(ABS(C11)>=10000,TEXT(ROUND(C11/10000,0),"#,##0")&"万円",TEXT(C11,"#,##0")&"円"))) | E11: (自動)
A13: 💸 月の生活費（『生活費』シートから自動反映）
B14: 月生活費（現在） | C14: =生活費!C17 | D14: =IF(NOT(ISNUMBER(C14)),"",IF(ABS(C14)>=100000000,TEXT(INT(C14/100000000),"0")&"億"&IF(MOD(C14,100000000)>=10000,TEXT(ROUND(MOD(C14,100000000)/10000,0),"#,##0")&"万円","円"),IF(ABS(C14)>=10000,TEXT(ROUND(C14/10000,0),"#,##0")&"万円",TEXT(C14,"#,##0")&"円"))) | E14: ← 編集は『生活費』シートで
B15: 🔢 月貯蓄可能額 | C15: =C9-C14 | D15: =IF(NOT(ISNUMBER(C15)),"",IF(ABS(C15)>=100000000,TEXT(INT(C15/100000000),"0")&"億"&IF(MOD(C15,100000000)>=10000,TEXT(ROUND(MOD(C15,100000000)/10000,0),"#,##0")&"万円","円"),IF(ABS(C15)>=10000,TEXT(ROUND(C15/10000,0),"#,##0")&"万円",TEXT(C15,"#,##0")&"円"))) | E15: (月収 − 月生活費)
B16: 🔢 年貯蓄可能額（ボーナス込） | C16: =C15*12+C10 | D16: =IF(NOT(ISNUMBER(C16)),"",IF(ABS(C16)>=100000000,TEXT(INT(C16/100000000),"0")&"億"&IF(MOD(C16,100000000)>=10000,TEXT(ROUND(MOD(C16,100000000)/10000,0),"#,##0")&"万円","円"),IF(ABS(C16)>=10000,TEXT(ROUND(C16/10000,0),"#,##0")&"万円",TEXT(C16,"#,##0")&"円")))
A18: 🏦 今ある資産（貯金と運用を分けて入力）
B19: 現在の貯金（現金・利率0%） | C19: 500000 | D19: =IF(NOT(ISNUMBER(C19)),"",IF(ABS(C19)>=100000000,TEXT(INT(C19/100000000),"0")&"億"&IF(MOD(C19,100000000)>=10000,TEXT(ROUND(MOD(C19,100000000)/10000,0),"#,##0")&"万円","円"),IF(ABS(C19)>=10000,TEXT(ROUND(C19/10000,0),"#,##0")&"万円",TEXT(C19,"#,##0")&"円"))) | E19: (銀行預金など)
B20: 現在の運用資産（投資中・年利で成長） | C20: 1500000 | D20: =IF(NOT(ISNUMBER(C20)),"",IF(ABS(C20)>=100000000,TEXT(INT(C20/100000000),"0")&"億"&IF(MOD(C20,100000000)>=10000,TEXT(ROUND(MOD(C20,100000000)/10000,0),"#,##0")&"万円","円"),IF(ABS(C20)>=10000,TEXT(ROUND(C20/10000,0),"#,##0")&"万円",TEXT(C20,"#,##0")&"円"))) | E20: (NISA・iDeCo等の投信)
B21: 🔢 総資産（現在） | C21: =C19+C20 | D21: =IF(NOT(ISNUMBER(C21)),"",IF(ABS(C21)>=100000000,TEXT(INT(C21/100000000),"0")&"億"&IF(MOD(C21,100000000)>=10000,TEXT(ROUND(MOD(C21,100000000)/10000,0),"#,##0")&"万円","円"),IF(ABS(C21)>=10000,TEXT(ROUND(C21/10000,0),"#,##0")&"万円",TEXT(C21,"#,##0")&"円")))
A23: 📈 投資設定
B24: 月積立額（投資への積立） | C24: 150000 | D24: =IF(NOT(ISNUMBER(C24)),"",IF(ABS(C24)>=100000000,TEXT(INT(C24/100000000),"0")&"億"&IF(MOD(C24,100000000)>=10000,TEXT(ROUND(MOD(C24,100000000)/10000,0),"#,##0")&"万円","円"),IF(ABS(C24)>=10000,TEXT(ROUND(C24/10000,0),"#,##0")&"万円",TEXT(C24,"#,##0")&"円"))) | E24: (NISA+iDeCo合計)
B25: 想定年利 | C25: 0.05 | E25: (オルカン+SP500で5-6%)
A27: 🎯 サイドFIRE後の想定
B28: FIRE後の月生活費（『生活費』シート参照） | C28: =生活費!C32 | D28: =IF(NOT(ISNUMBER(C28)),"",IF(ABS(C28)>=100000000,TEXT(INT(C28/100000000),"0")&"億"&IF(MOD(C28,100000000)>=10000,TEXT(ROUND(MOD(C28,100000000)/10000,0),"#,##0")&"万円","円"),IF(ABS(C28)>=10000,TEXT(ROUND(C28/10000,0),"#,##0")&"万円",TEXT(C28,"#,##0")&"円"))) | E28: ← 編集は『生活費』シートで
B29: FIRE後の月副業収入 | C29: 100000 | D29: =IF(NOT(ISNUMBER(C29)),"",IF(ABS(C29)>=100000000,TEXT(INT(C29/100000000),"0")&"億"&IF(MOD(C29,100000000)>=10000,TEXT(ROUND(MOD(C29,100000000)/10000,0),"#,##0")&"万円","円"),IF(ABS(C29)>=10000,TEXT(ROUND(C29/10000,0),"#,##0")&"万円",TEXT(C29,"#,##0")&"円"))) | E29: (緩い労働で稼ぐ分)

Sheet 結論
A1: 🐪 | B1: 🎯 結論｜あなたのサイドFIRE達成診断
B2: 上から順に読むだけで全部わかる / 値の右に万円表示
B4: 🎉 サイドFIRE 達成可否
B5: =IF(C17>=C11,"✓ 達成見込み！おめでとう🐪","✗ 達成にあと一歩")
A7: Step 1: 必要な総資産を計算（4%ルール）
B8: FIRE後の年生活費 | C8: =入力!$C$28*12 | D8: =IF(NOT(ISNUMBER(C8)),"",IF(ABS(C8)>=100000000,TEXT(INT(C8/100000000),"0")&"億"&IF(MOD(C8,100000000)>=10000,TEXT(ROUND(MOD(C8,100000000)/10000,0),"#,##0")&"万円","円"),IF(ABS(C8)>=10000,TEXT(ROUND(C8/10000,0),"#,##0")&"万円",TEXT(C8,"#,##0")&"円")))
B9: FIRE後の年副業収入 | C9: =入力!$C$29*12 | D9: =IF(NOT(ISNUMBER(C9)),"",IF(ABS(C9)>=100000000,TEXT(INT(C9/100000000),"0")&"億"&IF(MOD(C9,100000000)>=10000,TEXT(ROUND(MOD(C9,100000000)/10000,0),"#,##0")&"万円","円"),IF(ABS(C9)>=10000,TEXT(ROUND(C9/10000,0),"#,##0")&"万円",TEXT(C9,"#,##0")&"円")))
B10: 資産取崩しが必要な年額 | C10: =C8-C9 | D10: =IF(NOT(ISNUMBER(C10)),"",IF(ABS(C10)>=100000000,TEXT(INT(C10/100000000),"0")&"億"&IF(MOD(C10,100000000)>=10000,TEXT(ROUND(MOD(C10,100000000)/10000,0),"#,##0")&"万円","円"),IF(ABS(C10)>=10000,TEXT(ROUND(C10/10000,0),"#,##0")&"万円",TEXT(C10,"#,##0")&"円"))) | E10: =年生活費 − 年副業
B11: 💡 サイドFIRE 必要総資産 | C11: =C10*25 | D11: =IF(NOT(ISNUMBER(C11)),"",IF(ABS(C11)>=100000000,TEXT(INT(C11/100000000),"0")&"億"&IF(MOD(C11,100000000)>=10000,TEXT(ROUND(MOD(C11,100000000)/10000,0),"#,##0")&"万円","円"),IF(ABS(C11)>=10000,TEXT(ROUND(C11/10000,0),"#,##0")&"万円",TEXT(C11,"#,##0")&"円"))) | E11: (年取崩額 × 25倍)
A13: Step 2: 目標年齢時に達成できる資産
B14: 目標FIREまでの年数 | C14: =入力!$C$6-入力!$C$5
B15: 💧 目標年齢時の貯金（現金・成長なし） | C15: =入力!$C$19 | D15: =IF(NOT(ISNUMBER(C15)),"",IF(ABS(C15)>=100000000,TEXT(INT(C15/100000000),"0")&"億"&IF(MOD(C15,100000000)>=10000,TEXT(ROUND(MOD(C15,100000000)/10000,0),"#,##0")&"万円","円"),IF(ABS(C15)>=10000,TEXT(ROUND(C15/10000,0),"#,##0")&"万円",TEXT(C15,"#,##0")&"円"))) | E15: (現金は複利成長しない前提)
B16: 📈 目標年齢時の運用資産（複利成長） | C16: =FV(入力!$C$25/12,C14*12,-入力!$C$24,-入力!$C$20) | D16: =IF(NOT(ISNUMBER(C16)),"",IF(ABS(C16)>=100000000,TEXT(INT(C16/100000000),"0")&"億"&IF(MOD(C16,100000000)>=10000,TEXT(ROUND(MOD(C16,100000000)/10000,0),"#,##0")&"万円","円"),IF(ABS(C16)>=10000,TEXT(ROUND(C16/10000,0),"#,##0")&"万円",TEXT(C16,"#,##0")&"円"))) | E16: (月積立を続けた前提)
B17: 💰 目標年齢時の予想総資産 | C17: =C15+C16 | D17: =IF(NOT(ISNUMBER(C17)),"",IF(ABS(C17)>=100000000,TEXT(INT(C17/100000000),"0")&"億"&IF(MOD(C17,100000000)>=10000,TEXT(ROUND(MOD(C17,100000000)/10000,0),"#,##0")&"万円","円"),IF(ABS(C17)>=10000,TEXT(ROUND(C17/10000,0),"#,##0")&"万円",TEXT(C17,"#,##0")&"円")))
A19: Step 3: 達成診断（数字で見る）
B20: 📊 達成率 | C20: =C17/C11
B21: 📉 不足額（達成にあといくら必要？） | C21: =MAX(0,C11-C17) | D21: =IF(NOT(ISNUMBER(C21)),"",IF(ABS(C21)>=100000000,TEXT(INT(C21/100000000),"0")&"億"&IF(MOD(C21,100000000)>=10000,TEXT(ROUND(MOD(C21,100000000)/10000,0),"#,##0")&"万円","円"),IF(ABS(C21)>=10000,TEXT(ROUND(C21/10000,0),"#,##0")&"万円",TEXT(C21,"#,##0")&"円")))
B22: 📈 月積立をあといくら増やせば達成？ | C22: =IFERROR(MAX(0,(PMT(入力!$C$25/12,C14*12,-入力!$C$20,-(C11-C15))-(-入力!$C$24))*-1),0) | D22: =IF(NOT(ISNUMBER(C22)),"",IF(ABS(C22)>=100000000,TEXT(INT(C22/100000000),"0")&"億"&IF(MOD(C22,100000000)>=10000,TEXT(ROUND(MOD(C22,100000000)/10000,0),"#,##0")&"万円","円"),IF(ABS(C22)>=10000,TEXT(ROUND(C22/10000,0),"#,##0")&"万円",TEXT(C22,"#,##0")&"円")))
A24: Step 4: 別の見方で確認
B25: 現状ペース継続 → 必要額到達は何歳？ | C25: =IFERROR(入力!$C$5+ROUND(NPER(入力!$C$25/12,-入力!$C$24,-入力!$C$20,C11-入力!$C$19)/12,0)&"歳","計算不能") | E25: (月積立を続けて何歳で達成？)
B26: 達成資産で何年もつ？（運用継続前提） | C26: =IF(C10<=0,"永久に",IF(C17*入力!$C$25>=C10,"永久に減らない（運用益で賄える）",IFERROR(ROUND(NPER(入力!$C$25/12,-C10/12,C17)/12,1)&"年","計算不能"))) | E26: (取崩し中も年利で運用続けた場合)
B27: FIRE達成までの月貯蓄ペース | C27: =入力!$C$15 | D27: =IF(NOT(ISNUMBER(C27)),"",IF(ABS(C27)>=100000000,TEXT(INT(C27/100000000),"0")&"億"&IF(MOD(C27,100000000)>=10000,TEXT(ROUND(MOD(C27,100000000)/10000,0),"#,##0")&"万円","円"),IF(ABS(C27)>=10000,TEXT(ROUND(C27/10000,0),"#,##0")&"万円",TEXT(C27,"#,##0")&"円"))) | E27: (月収−月生活費)
A29: Step 5: ここを動かせば達成できる（自動計算）
B30: 変える項目 | C30: 現状 | D30: → 達成ライン | E30: 一言メモ
B31: A. 月積立を増やす | C31: =TEXT(ROUND(入力!$C$24/10000,1),"0.0")&"万円/月" | D31: =IF(C17>=C11,"現状で達成済",TEXT(ROUND((入力!$C$24+C22)/10000,1),"0.0")&"万円/月") | E31: 投資への月積立額
B32: B. FIRE開始年齢を遅らせる | C32: =入力!$C$6&"歳" | D32: =IF(C17>=C11,"現状で達成済",IFERROR(ROUND(入力!$C$5+NPER(入力!$C$25/12,-入力!$C$24,-入力!$C$20,C11-入力!$C$19)/12,0)&"歳","計算不能")) | E32: 資産が貯まる年齢まで働く
B33: C. FIRE後副業を増やす | C33: =TEXT(ROUND(入力!$C$29/10000,1),"0.0")&"万円/月" | D33: =IF(C17>=C11,"現状で達成済",TEXT(ROUND(MAX(入力!$C$29,(C8-C17/25)/12)/10000,1),"0.0")&"万円/月") | E33: セミリタイア後の月収
B34: D. FIRE後生活費を下げる | C34: =TEXT(ROUND(入力!$C$28/10000,1),"0.0")&"万円/月" | D34: =IF(C17>=C11,"現状で達成済",TEXT(ROUND(MIN(入力!$C$28,(C17/25+C9)/12)/10000,1),"0.0")&"万円/月") | E34: 『生活費』シートのFIRE後を調整

Sheet 年次推移
A1: 🐪 | B1: 📊 年次推移｜年齢別の資産
B2: 現状ペース継続したら各年齢でいくら？
A4: 現状ペース継続したら各年齢でいくら？
B5: 年齢 | C5: 経過 | D5: 💧 貯金 | E5: 📈 運用FV | F5: 💰 総資産 | G5: 総資産（万円表示） | H5: 必要資産との差
B6: =入力!$C$5+0 | C6: 0 | D6: =入力!$C$19 | E6: =入力!$C$20 | F6: =D6+E6 | G6: =IF(NOT(ISNUMBER(F6)),"",IF(ABS(F6)>=100000000,TEXT(INT(F6/100000000),"0")&"億"&IF(MOD(F6,100000000)>=10000,TEXT(ROUND(MOD(F6,100000000)/10000,0),"#,##0")&"万円","円"),IF(ABS(F6)>=10000,TEXT(ROUND(F6/10000,0),"#,##0")&"万円",TEXT(F6,"#,##0")&"円"))) | H6: =F6-結論!C11
B7: =入力!$C$5+1 | C7: 1 | D7: =入力!$C$19 | E7: =FV(入力!$C$25/12,1*12,-入力!$C$24,-入力!$C$20) | F7: =D7+E7 | G7: =IF(NOT(ISNUMBER(F7)),"",IF(ABS(F7)>=100000000,TEXT(INT(F7/100000000),"0")&"億"&IF(MOD(F7,100000000)>=10000,TEXT(ROUND(MOD(F7,100000000)/10000,0),"#,##0")&"万円","円"),IF(ABS(F7)>=10000,TEXT(ROUND(F7/10000,0),"#,##0")&"万円",TEXT(F7,"#,##0")&"円"))) | H7: =F7-結論!C11
B8: =入力!$C$5+2 | C8: 2 | D8: =入力!$C$19 | E8: =FV(入力!$C$25/12,2*12,-入力!$C$24,-入力!$C$20) | F8: =D8+E8 | G8: =IF(NOT(ISNUMBER(F8)),"",IF(ABS(F8)>=100000000,TEXT(INT(F8/100000000),"0")&"億"&IF(MOD(F8,100000000)>=10000,TEXT(ROUND(MOD(F8,100000000)/10000,0),"#,##0")&"万円","円"),IF(ABS(F8)>=10000,TEXT(ROUND(F8/10000,0),"#,##0")&"万円",TEXT(F8,"#,##0")&"円"))) | H8: =F8-結論!C11
B9: =入力!$C$5+3 | C9: 3 | D9: =入力!$C$19 | E9: =FV(入力!$C$25/12,3*12,-入力!$C$24,-入力!$C$20) | F9: =D9+E9 | G9: =IF(NOT(ISNUMBER(F9)),"",IF(ABS(F9)>=100000000,TEXT(INT(F9/100000000),"0")&"億"&IF(MOD(F9,100000000)>=10000,TEXT(ROUND(MOD(F9,100000000)/10000,0),"#,##0")&"万円","円"),IF(ABS(F9)>=10000,TEXT(ROUND(F9/10000,0),"#,##0")&"万円",TEXT(F9,"#,##0")&"円"))) | H9: =F9-結論!C11
B10: =入力!$C$5+4 | C10: 4 | D10: =入力!$C$19 | E10: =FV(入力!$C$25/12,4*12,-入力!$C$24,-入力!$C$20) | F10: =D10+E10 | G10: =IF(NOT(ISNUMBER(F10)),"",IF(ABS(F10)>=100000000,TEXT(INT(F10/100000000),"0")&"億"&IF(MOD(F10,100000000)>=10000,TEXT(ROUND(MOD(F10,100000000)/10000,0),"#,##0")&"万円","円"),IF(ABS(F10)>=10000,TEXT(ROUND(F10/10000,0),"#,##0")&"万円",TEXT(F10,"#,##0")&"円"))) | H10: =F10-結論!C11
B11: =入力!$C$5+5 | C11: 5 | D11: =入力!$C$19 | E11: =FV(入力!$C$25/12,5*12,-入力!$C$24,-入力!$C$20) | F11: =D11+E11 | G11: =IF(NOT(ISNUMBER(F11)),"",IF(ABS(F11)>=100000000,TEXT(INT(F11/100000000),"0")&"億"&IF(MOD(F11,100000000)>=10000,TEXT(ROUND(MOD(F11,100000000)/10000,0),"#,##0")&"万円","円"),IF(ABS(F11)>=10000,TEXT(ROUND(F11/10000,0),"#,##0")&"万円",TEXT(F11,"#,##0")&"円"))) | H11: =F11-結論!C11
B12: =入力!$C$5+6 | C12: 6 | D12: =入力!$C$19 | E12: =FV(入力!$C$25/12,6*12,-入力!$C$24,-入力!$C$20) | F12: =D12+E12 | G12: =IF(NOT(ISNUMBER(F12)),"",IF(ABS(F12)>=100000000,TEXT(INT(F12/100000000),"0")&"億"&IF(MOD(F12,100000000)>=10000,TEXT(ROUND(MOD(F12,100000000)/10000,0),"#,##0")&"万円","円"),IF(ABS(F12)>=10000,TEXT(ROUND(F12/10000,0),"#,##0")&"万円",TEXT(F12,"#,##0")&"円"))) | H12: =F12-結論!C11
B13: =入力!$C$5+7 | C13: 7 | D13: =入力!$C$19 | E13: =FV(入力!$C$25/12,7*12,-入力!$C$24,-入力!$C$20) | F13: =D13+E13 | G13: =IF(NOT(ISNUMBER(F13)),"",IF(ABS(F13)>=100000000,TEXT(INT(F13/100000000),"0")&"億"&IF(MOD(F13,100000000)>=10000,TEXT(ROUND(MOD(F13,100000000)/10000,0),"#,##0")&"万円","円"),IF(ABS(F13)>=10000,TEXT(ROUND(F13/10000,0),"#,##0")&"万円",TEXT(F13,"#,##0")&"円"))) | H13: =F13-結論!C11
B14: =入力!$C$5+8 | C14: 8 | D14: =入力!$C$19 | E14: =FV(入力!$C$25/12,8*12,-入力!$C$24,-入力!$C$20) | F14: =D14+E14 | G14: =IF(NOT(ISNUMBER(F14)),"",IF(ABS(F14)>=100000000,TEXT(INT(F14/100000000),"0")&"億"&IF(MOD(F14,100000000)>=10000,TEXT(ROUND(MOD(F14,100000000)/10000,0),"#,##0")&"万円","円"),IF(ABS(F14)>=10000,TEXT(ROUND(F14/10000,0),"#,##0")&"万円",TEXT(F14,"#,##0")&"円"))) | H14: =F14-結論!C11
B15: =入力!$C$5+9 | C15: 9 | D15: =入力!$C$19 | E15: =FV(入力!$C$25/12,9*12,-入力!$C$24,-入力!$C$20) | F15: =D15+E15 | G15: =IF(NOT(ISNUMBER(F15)),"",IF(ABS(F15)>=100000000,TEXT(INT(F15/100000000),"0")&"億"&IF(MOD(F15,100000000)>=10000,TEXT(ROUND(MOD(F15,100000000)/10000,0),"#,##0")&"万円","円"),IF(ABS(F15)>=10000,TEXT(ROUND(F15/10000,0),"#,##0")&"万円",TEXT(F15,"#,##0")&"円"))) | H15: =F15-結論!C11
B16: =入力!$C$5+10 | C16: 10 | D16: =入力!$C$19 | E16: =FV(入力!$C$25/12,10*12,-入力!$C$24,-入力!$C$20) | F16: =D16+E16 | G16: =IF(NOT(ISNUMBER(F16)),"",IF(ABS(F16)>=100000000,TEXT(INT(F16/100000000),"0")&"億"&IF(MOD(F16,100000000)>=10000,TEXT(ROUND(MOD(F16,100000000)/10000,0),"#,##0")&"万円","円"),IF(ABS(F16)>=10000,TEXT(ROUND(F16/10000,0),"#,##0")&"万円",TEXT(F16,"#,##0")&"円"))) | H16: =F16-結論!C11
B17: =入力!$C$5+11 | C17: 11 | D17: =入力!$C$19 | E17: =FV(入力!$C$25/12,11*12,-入力!$C$24,-入力!$C$20) | F17: =D17+E17 | G17: =IF(NOT(ISNUMBER(F17)),"",IF(ABS(F17)>=100000000,TEXT(INT(F17/100000000),"0")&"億"&IF(MOD(F17,100000000)>=10000,TEXT(ROUND(MOD(F17,100000000)/10000,0),"#,##0")&"万円","円"),IF(ABS(F17)>=10000,TEXT(ROUND(F17/10000,0),"#,##0")&"万円",TEXT(F17,"#,##0")&"円"))) | H17: =F17-結論!C11
B18: =入力!$C$5+12 | C18: 12 | D18: =入力!$C$19 | E18: =FV(入力!$C$25/12,12*12,-入力!$C$24,-入力!$C$20) | F18: =D18+E18 | G18: =IF(NOT(ISNUMBER(F18)),"",IF(ABS(F18)>=100000000,TEXT(INT(F18/100000000),"0")&"億"&IF(MOD(F18,100000000)>=10000,TEXT(ROUND(MOD(F18,100000000)/10000,0),"#,##0")&"万円","円"),IF(ABS(F18)>=10000,TEXT(ROUND(F18/10000,0),"#,##0")&"万円",TEXT(F18,"#,##0")&"円"))) | H18: =F18-結論!C11
B19: =入力!$C$5+13 | C19: 13 | D19: =入力!$C$19 | E19: =FV(入力!$C$25/12,13*12,-入力!$C$24,-入力!$C$20) | F19: =D19+E19 | G19: =IF(NOT(ISNUMBER(F19)),"",IF(ABS(F19)>=100000000,TEXT(INT(F19/100000000),"0")&"億"&IF(MOD(F19,100000000)>=10000,TEXT(ROUND(MOD(F19,100000000)/10000,0),"#,##0")&"万円","円"),IF(ABS(F19)>=10000,TEXT(ROUND(F19/10000,0),"#,##0")&"万円",TEXT(F19,"#,##0")&"円"))) | H19: =F19-結論!C11
B20: =入力!$C$5+14 | C20: 14 | D20: =入力!$C$19 | E20: =FV(入力!$C$25/12,14*12,-入力!$C$24,-入力!$C$20) | F20: =D20+E20 | G20: =IF(NOT(ISNUMBER(F20)),"",IF(ABS(F20)>=100000000,TEXT(INT(F20/100000000),"0")&"億"&IF(MOD(F20,100000000)>=10000,TEXT(ROUND(MOD(F20,100000000)/10000,0),"#,##0")&"万円","円"),IF(ABS(F20)>=10000,TEXT(ROUND(F20/10000,0),"#,##0")&"万円",TEXT(F20,"#,##0")&"円"))) | H20: =F20-結論!C11
B21: =入力!$C$5+15 | C21: 15 | D21: =入力!$C$19 | E21: =FV(入力!$C$25/12,15*12,-入力!$C$24,-入力!$C$20) | F21: =D21+E21 | G21: =IF(NOT(ISNUMBER(F21)),"",IF(ABS(F21)>=100000000,TEXT(INT(F21/100000000),"0")&"億"&IF(MOD(F21,100000000)>=10000,TEXT(ROUND(MOD(F21,100000000)/10000,0),"#,##0")&"万円","円"),IF(ABS(F21)>=10000,TEXT(ROUND(F21/10000,0),"#,##0")&"万円",TEXT(F21,"#,##0")&"円"))) | H21: =F21-結論!C11
B22: =入力!$C$5+16 | C22: 16 | D22: =入力!$C$19 | E22: =FV(入力!$C$25/12,16*12,-入力!$C$24,-入力!$C$20) | F22: =D22+E22 | G22: =IF(NOT(ISNUMBER(F22)),"",IF(ABS(F22)>=100000000,TEXT(INT(F22/100000000),"0")&"億"&IF(MOD(F22,100000000)>=10000,TEXT(ROUND(MOD(F22,100000000)/10000,0),"#,##0")&"万円","円"),IF(ABS(F22)>=10000,TEXT(ROUND(F22/10000,0),"#,##0")&"万円",TEXT(F22,"#,##0")&"円"))) | H22: =F22-結論!C11
B23: =入力!$C$5+17 | C23: 17 | D23: =入力!$C$19 | E23: =FV(入力!$C$25/12,17*12,-入力!$C$24,-入力!$C$20) | F23: =D23+E23 | G23: =IF(NOT(ISNUMBER(F23)),"",IF(ABS(F23)>=100000000,TEXT(INT(F23/100000000),"0")&"億"&IF(MOD(F23,100000000)>=10000,TEXT(ROUND(MOD(F23,100000000)/10000,0),"#,##0")&"万円","円"),IF(ABS(F23)>=10000,TEXT(ROUND(F23/10000,0),"#,##0")&"万円",TEXT(F23,"#,##0")&"円"))) | H23: =F23-結論!C11
B24: =入力!$C$5+18 | C24: 18 | D24: =入力!$C$19 | E24: =FV(入力!$C$25/12,18*12,-入力!$C$24,-入力!$C$20) | F24: =D24+E24 | G24: =IF(NOT(ISNUMBER(F24)),"",IF(ABS(F24)>=100000000,TEXT(INT(F24/100000000),"0")&"億"&IF(MOD(F24,100000000)>=10000,TEXT(ROUND(MOD(F24,100000000)/10000,0),"#,##0")&"万円","円"),IF(ABS(F24)>=10000,TEXT(ROUND(F24/10000,0),"#,##0")&"万円",TEXT(F24,"#,##0")&"円"))) | H24: =F24-結論!C11
B25: =入力!$C$5+19 | C25: 19 | D25: =入力!$C$19 | E25: =FV(入力!$C$25/12,19*12,-入力!$C$24,-入力!$C$20) | F25: =D25+E25 | G25: =IF(NOT(ISNUMBER(F25)),"",IF(ABS(F25)>=100000000,TEXT(INT(F25/100000000),"0")&"億"&IF(MOD(F25,100000000)>=10000,TEXT(ROUND(MOD(F25,100000000)/10000,0),"#,##0")&"万円","円"),IF(ABS(F25)>=10000,TEXT(ROUND(F25/10000,0),"#,##0")&"万円",TEXT(F25,"#,##0")&"円"))) | H25: =F25-結論!C11
B26: =入力!$C$5+20 | C26: 20 | D26: =入力!$C$19 | E26: =FV(入力!$C$25/12,20*12,-入力!$C$24,-入力!$C$20) | F26: =D26+E26 | G26: =IF(NOT(ISNUMBER(F26)),"",IF(ABS(F26)>=100000000,TEXT(INT(F26/100000000),"0")&"億"&IF(MOD(F26,100000000)>=10000,TEXT(ROUND(MOD(F26,100000000)/10000,0),"#,##0")&"万円","円"),IF(ABS(F26)>=10000,TEXT(ROUND(F26/10000,0),"#,##0")&"万円",TEXT(F26,"#,##0")&"円"))) | H26: =F26-結論!C11
B27: =入力!$C$5+21 | C27: 21 | D27: =入力!$C$19 | E27: =FV(入力!$C$25/12,21*12,-入力!$C$24,-入力!$C$20) | F27: =D27+E27 | G27: =IF(NOT(ISNUMBER(F27)),"",IF(ABS(F27)>=100000000,TEXT(INT(F27/100000000),"0")&"億"&IF(MOD(F27,100000000)>=10000,TEXT(ROUND(MOD(F27,100000000)/10000,0),"#,##0")&"万円","円"),IF(ABS(F27)>=10000,TEXT(ROUND(F27/10000,0),"#,##0")&"万円",TEXT(F27,"#,##0")&"円"))) | H27: =F27-結論!C11
B28: =入力!$C$5+22 | C28: 22 | D28: =入力!$C$19 | E28: =FV(入力!$C$25/12,22*12,-入力!$C$24,-入力!$C$20) | F28: =D28+E28 | G28: =IF(NOT(ISNUMBER(F28)),"",IF(ABS(F28)>=100000000,TEXT(INT(F28/100000000),"0")&"億"&IF(MOD(F28,100000000)>=10000,TEXT(ROUND(MOD(F28,100000000)/10000,0),"#,##0")&"万円","円"),IF(ABS(F28)>=10000,TEXT(ROUND(F28/10000,0),"#,##0")&"万円",TEXT(F28,"#,##0")&"円"))) | H28: =F28-結論!C11
B29: =入力!$C$5+23 | C29: 23 | D29: =入力!$C$19 | E29: =FV(入力!$C$25/12,23*12,-入力!$C$24,-入力!$C$20) | F29: =D29+E29 | G29: =IF(NOT(ISNUMBER(F29)),"",IF(ABS(F29)>=100000000,TEXT(INT(F29/100000000),"0")&"億"&IF(MOD(F29,100000000)>=10000,TEXT(ROUND(MOD(F29,100000000)/10000,0),"#,##0")&"万円","円"),IF(ABS(F29)>=10000,TEXT(ROUND(F29/10000,0),"#,##0")&"万円",TEXT(F29,"#,##0")&"円"))) | H29: =F29-結論!C11
B30: =入力!$C$5+24 | C30: 24 | D30: =入力!$C$19 | E30: =FV(入力!$C$25/12,24*12,-入力!$C$24,-入力!$C$20) | F30: =D30+E30 | G30: =IF(NOT(ISNUMBER(F30)),"",IF(ABS(F30)>=100000000,TEXT(INT(F30/100000000),"0")&"億"&IF(MOD(F30,100000000)>=10000,TEXT(ROUND(MOD(F30,100000000)/10000,0),"#,##0")&"万円","円"),IF(ABS(F30)>=10000,TEXT(ROUND(F30/10000,0),"#,##0")&"万円",TEXT(F30,"#,##0")&"円"))) | H30: =F30-結論!C11
B31: =入力!$C$5+25 | C31: 25 | D31: =入力!$C$19 | E31: =FV(入力!$C$25/12,25*12,-入力!$C$24,-入力!$C$20) | F31: =D31+E31 | G31: =IF(NOT(ISNUMBER(F31)),"",IF(ABS(F31)>=100000000,TEXT(INT(F31/100000000),"0")&"億"&IF(MOD(F31,100000000)>=10000,TEXT(ROUND(MOD(F31,100000000)/10000,0),"#,##0")&"万円","円"),IF(ABS(F31)>=10000,TEXT(ROUND(F31/10000,0),"#,##0")&"万円",TEXT(F31,"#,##0")&"円"))) | H31: =F31-結論!C11
B32: =入力!$C$5+26 | C32: 26 | D32: =入力!$C$19 | E32: =FV(入力!$C$25/12,26*12,-入力!$C$24,-入力!$C$20) | F32: =D32+E32 | G32: =IF(NOT(ISNUMBER(F32)),"",IF(ABS(F32)>=100000000,TEXT(INT(F32/100000000),"0")&"億"&IF(MOD(F32,100000000)>=10000,TEXT(ROUND(MOD(F32,100000000)/10000,0),"#,##0")&"万円","円"),IF(ABS(F32)>=10000,TEXT(ROUND(F32/10000,0),"#,##0")&"万円",TEXT(F32,"#,##0")&"円"))) | H32: =F32-結論!C11
B33: =入力!$C$5+27 | C33: 27 | D33: =入力!$C$19 | E33: =FV(入力!$C$25/12,27*12,-入力!$C$24,-入力!$C$20) | F33: =D33+E33 | G33: =IF(NOT(ISNUMBER(F33)),"",IF(ABS(F33)>=100000000,TEXT(INT(F33/100000000),"0")&"億"&IF(MOD(F33,100000000)>=10000,TEXT(ROUND(MOD(F33,100000000)/10000,0),"#,##0")&"万円","円"),IF(ABS(F33)>=10000,TEXT(ROUND(F33/10000,0),"#,##0")&"万円",TEXT(F33,"#,##0")&"円"))) | H33: =F33-結論!C11
B34: =入力!$C$5+28 | C34: 28 | D34: =入力!$C$19 | E34: =FV(入力!$C$25/12,28*12,-入力!$C$24,-入力!$C$20) | F34: =D34+E34 | G34: =IF(NOT(ISNUMBER(F34)),"",IF(ABS(F34)>=100000000,TEXT(INT(F34/100000000),"0")&"億"&IF(MOD(F34,100000000)>=10000,TEXT(ROUND(MOD(F34,100000000)/10000,0),"#,##0")&"万円","円"),IF(ABS(F34)>=10000,TEXT(ROUND(F34/10000,0),"#,##0")&"万円",TEXT(F34,"#,##0")&"円"))) | H34: =F34-結論!C11
B35: =入力!$C$5+29 | C35: 29 | D35: =入力!$C$19 | E35: =FV(入力!$C$25/12,29*12,-入力!$C$24,-入力!$C$20) | F35: =D35+E35 | G35: =IF(NOT(ISNUMBER(F35)),"",IF(ABS(F35)>=100000000,TEXT(INT(F35/100000000),"0")&"億"&IF(MOD(F35,100000000)>=10000,TEXT(ROUND(MOD(F35,100000000)/10000,0),"#,##0")&"万円","円"),IF(ABS(F35)>=10000,TEXT(ROUND(F35/10000,0),"#,##0")&"万円",TEXT(F35,"#,##0")&"円"))) | H35: =F35-結論!C11
B36: =入力!$C$5+30 | C36: 30 | D36: =入力!$C$19 | E36: =FV(入力!$C$25/12,30*12,-入力!$C$24,-入力!$C$20) | F36: =D36+E36 | G36: =IF(NOT(ISNUMBER(F36)),"",IF(ABS(F36)>=100000000,TEXT(INT(F36/100000000),"0")&"億"&IF(MOD(F36,100000000)>=10000,TEXT(ROUND(MOD(F36,100000000)/10000,0),"#,##0")&"万円","円"),IF(ABS(F36)>=10000,TEXT(ROUND(F36/10000,0),"#,##0")&"万円",TEXT(F36,"#,##0")&"円"))) | H36: =F36-結論!C11
B37: =入力!$C$5+31 | C37: 31 | D37: =入力!$C$19 | E37: =FV(入力!$C$25/12,31*12,-入力!$C$24,-入力!$C$20) | F37: =D37+E37 | G37: =IF(NOT(ISNUMBER(F37)),"",IF(ABS(F37)>=100000000,TEXT(INT(F37/100000000),"0")&"億"&IF(MOD(F37,100000000)>=10000,TEXT(ROUND(MOD(F37,100000000)/10000,0),"#,##0")&"万円","円"),IF(ABS(F37)>=10000,TEXT(ROUND(F37/10000,0),"#,##0")&"万円",TEXT(F37,"#,##0")&"円"))) | H37: =F37-結論!C11
B38: =入力!$C$5+32 | C38: 32 | D38: =入力!$C$19 | E38: =FV(入力!$C$25/12,32*12,-入力!$C$24,-入力!$C$20) | F38: =D38+E38 | G38: =IF(NOT(ISNUMBER(F38)),"",IF(ABS(F38)>=100000000,TEXT(INT(F38/100000000),"0")&"億"&IF(MOD(F38,100000000)>=10000,TEXT(ROUND(MOD(F38,100000000)/10000,0),"#,##0")&"万円","円"),IF(ABS(F38)>=10000,TEXT(ROUND(F38/10000,0),"#,##0")&"万円",TEXT(F38,"#,##0")&"円"))) | H38: =F38-結論!C11
B39: =入力!$C$5+33 | C39: 33 | D39: =入力!$C$19 | E39: =FV(入力!$C$25/12,33*12,-入力!$C$24,-入力!$C$20) | F39: =D39+E39 | G39: =IF(NOT(ISNUMBER(F39)),"",IF(ABS(F39)>=100000000,TEXT(INT(F39/100000000),"0")&"億"&IF(MOD(F39,100000000)>=10000,TEXT(ROUND(MOD(F39,100000000)/10000,0),"#,##0")&"万円","円"),IF(ABS(F39)>=10000,TEXT(ROUND(F39/10000,0),"#,##0")&"万円",TEXT(F39,"#,##0")&"円"))) | H39: =F39-結論!C11
B40: =入力!$C$5+34 | C40: 34 | D40: =入力!$C$19 | E40: =FV(入力!$C$25/12,34*12,-入力!$C$24,-入力!$C$20) | F40: =D40+E40 | G40: =IF(NOT(ISNUMBER(F40)),"",IF(ABS(F40)>=100000000,TEXT(INT(F40/100000000),"0")&"億"&IF(MOD(F40,100000000)>=10000,TEXT(ROUND(MOD(F40,100000000)/10000,0),"#,##0")&"万円","円"),IF(ABS(F40)>=10000,TEXT(ROUND(F40/10000,0),"#,##0")&"万円",TEXT(F40,"#,##0")&"円"))) | H40: =F40-結論!C11
B41: =入力!$C$5+35 | C41: 35 | D41: =入力!$C$19 | E41: =FV(入力!$C$25/12,35*12,-入力!$C$24,-入力!$C$20) | F41: =D41+E41 | G41: =IF(NOT(ISNUMBER(F41)),"",IF(ABS(F41)>=100000000,TEXT(INT(F41/100000000),"0")&"億"&IF(MOD(F41,100000000)>=10000,TEXT(ROUND(MOD(F41,100000000)/10000,0),"#,##0")&"万円","円"),IF(ABS(F41)>=10000,TEXT(ROUND(F41/10000,0),"#,##0")&"万円",TEXT(F41,"#,##0")&"円"))) | H41: =F41-結論!C11
...

Sheet FIRE試算
A1: 🐪 | B1: 🔄 FIRE試算｜5パターン比較
A4: 月積立や期間を変えるとどうなる？
B5: シナリオ | C5: 月積立 | D5: 年利 | E5: 期間(年) | F5: 予想総資産 | G5: 予想総資産（万円） | H5: 備考
B6: ①現状ペース | C6: =入力!$C$24 | D6: =入力!$C$25 | E6: 10 | F6: =FV(D6/12,E6*12,-C6,-入力!$C$20)+入力!$C$19 | G6: =IF(NOT(ISNUMBER(F6)),"",IF(ABS(F6)>=100000000,TEXT(INT(F6/100000000),"0")&"億"&IF(MOD(F6,100000000)>=10000,TEXT(ROUND(MOD(F6,100000000)/10000,0),"#,##0")&"万円","円"),IF(ABS(F6)>=10000,TEXT(ROUND(F6/10000,0),"#,##0")&"万円",TEXT(F6,"#,##0")&"円"))) | H6: あなたの入力値そのまま
B7: ②積立 +5万 | C7: =入力!$C$24+50000 | D7: =入力!$C$25 | E7: 10 | F7: =FV(D7/12,E7*12,-C7,-入力!$C$20)+入力!$C$19 | G7: =IF(NOT(ISNUMBER(F7)),"",IF(ABS(F7)>=100000000,TEXT(INT(F7/100000000),"0")&"億"&IF(MOD(F7,100000000)>=10000,TEXT(ROUND(MOD(F7,100000000)/10000,0),"#,##0")&"万円","円"),IF(ABS(F7)>=10000,TEXT(ROUND(F7/10000,0),"#,##0")&"万円",TEXT(F7,"#,##0")&"円"))) | H7: 月積立を5万増やす
B8: ③年利 +1% | C8: =入力!$C$24 | D8: =入力!$C$25+0.01 | E8: 10 | F8: =FV(D8/12,E8*12,-C8,-入力!$C$20)+入力!$C$19 | G8: =IF(NOT(ISNUMBER(F8)),"",IF(ABS(F8)>=100000000,TEXT(INT(F8/100000000),"0")&"億"&IF(MOD(F8,100000000)>=10000,TEXT(ROUND(MOD(F8,100000000)/10000,0),"#,##0")&"万円","円"),IF(ABS(F8)>=10000,TEXT(ROUND(F8/10000,0),"#,##0")&"万円",TEXT(F8,"#,##0")&"円"))) | H8: 投資配分をやや攻めに
B9: ④期間 +5年 | C9: =入力!$C$24 | D9: =入力!$C$25 | E9: 15 | F9: =FV(D9/12,E9*12,-C9,-入力!$C$20)+入力!$C$19 | G9: =IF(NOT(ISNUMBER(F9)),"",IF(ABS(F9)>=100000000,TEXT(INT(F9/100000000),"0")&"億"&IF(MOD(F9,100000000)>=10000,TEXT(ROUND(MOD(F9,100000000)/10000,0),"#,##0")&"万円","円"),IF(ABS(F9)>=10000,TEXT(ROUND(F9/10000,0),"#,##0")&"万円",TEXT(F9,"#,##0")&"円"))) | H9: 5年長く働く
B10: ⑤積立0で運用のみ | C10: 0 | D10: =入力!$C$25 | E10: 10 | F10: =FV(D10/12,E10*12,-C10,-入力!$C$20)+入力!$C$19 | G10: =IF(NOT(ISNUMBER(F10)),"",IF(ABS(F10)>=100000000,TEXT(INT(F10/100000000),"0")&"億"&IF(MOD(F10,100000000)>=10000,TEXT(ROUND(MOD(F10,100000000)/10000,0),"#,##0")&"万円","円"),IF(ABS(F10)>=10000,TEXT(ROUND(F10/10000,0),"#,##0")&"万円",TEXT(F10,"#,##0")&"円"))) | H10: 今ある資産だけ運用

Sheet らくだ先生について
A1: 🐪 | B1: 残業嫌いのらくだ先生
A3: ■ | B3: プロフィール
B4: 公立中学校教員（国語・20代）
B5: ICT・AIで残業ゼロ ｜ 副業10万 ｜ 5年で2000万円貯金
B6: 日本株デイトレで-50万やった失敗から、低リスクインデックス投資に振り切り。
A8: ■ | B8: 発信中
B9: X (Twitter): @rakuda_sensei
B10: note: https://note.com/rakuda_sensei
B11: BOOTH: https://rakuda-sensei.booth.pm
A13: ■ | B13: ご利用について
B14: ・本商品の個人利用は自由
B15: ・二次配布・転売は禁止
B16: ・本商品の数式・テンプレで生じた結果について作者は責任を負いません
B17: ・改善要望・不具合報告は X DM までお気軽に
